<?xml version="1.0" encoding="utf-8"?>
<robot   name="robotfin" xmlns:xacro="http://www.ros.org/wiki/xacro">
  <xacro:include filename="$(find rtvfin)/src/robotfin_description/urdf/robots.gazebo.xacro" /> 
  <link  name="base_link">
    <inertial>
      <origin
        xyz="-0.128869691542532 0.0307574867015144 -0.142834733522175"
        rpy="0 0 0" />
      <mass
        value="6.85097974966862" />
      <inertia
        ixx="0.137818258795601"
        ixy="-1.11155480239264E-17"
        ixz="-3.46831745116903E-17"
        iyy="0.186267949899407"
        iyz="-0.0105315145068748"
        izz="0.0665498950747064" />
    </inertial>
    <visual>
      <origin
        xyz="0 0 0"
        rpy="0 0 0" />
      <geometry>
        <mesh
          filename="package://robotfin/meshes/base_link.STL" />
      </geometry>
      <material
        name="">
        <color
          rgba="0 0.87843137254902 0.164705882352941 1" />
      </material>
    </visual>
    <collision>
      <origin
        xyz="0 0 0"
        rpy="0 0 0" />
      <geometry>
        <mesh
          filename="package://robotfin/meshes/base_link.STL" />
      </geometry>
    </collision>
  </link>
  <link  name="Small_Link">
    <inertial>
      <origin
        xyz="2.5489308217358E-05 4.248218036218E-05 0.0768785031315431"
        rpy="0 0 0" />
      <mass
        value="0.166163303218961" />
      <inertia
        ixx="0.000168874660678989"
        ixy="-1.83852268579996E-07"
        ixz="1.69959766583105E-07"
        iyy="0.00017042195032223"
        iyz="2.83266277638508E-07"
        izz="0.000217435788583874" />
    </inertial>
    <visual>
      <origin
        xyz="0 0 0"
        rpy="0 0 0" />
      <geometry>
        <mesh
          filename="package://robotfin/meshes/Small_Link.STL" />
      </geometry>
      <material
        name="">
        <color
          rgba="0.384313725490196 0.462745098039216 1 1" />
      </material>
    </visual>
    <collision>
      <origin
        xyz="0 0 0"
        rpy="0 0 0" />
      <geometry>
        <mesh
          filename="package://robotfin/meshes/Small_Link.STL" />
      </geometry>
    </collision>
  </link>
  <joint name="small_link"
    type="fixed">
    <origin
      xyz="-0.12887 0.345 0"
      rpy="3.1416 0 0" />
    <parent
      link="base_link" />
    <child
      link="Small_Link" />
    <axis
      xyz="0 0 1" />
  </joint>
  <link  name="Lidar_Link">
    <inertial>
      <origin
        xyz="1.38777878078145E-17 1.38777878078145E-17 0.0342165768302536"
        rpy="0 0 0" />
      <mass
        value="0.491430460551326" />
      <inertia
        ixx="0.000499328268367785"
        ixy="0"
        ixz="3.40380278202547E-20"
        iyy="0.000499328268367785"
        iyz="-1.81411866028494E-20"
        izz="0.000517286112813611" />
    </inertial>
    <visual>
      <origin
        xyz="0 0 0"
        rpy="0 0 0" />
      <geometry>
        <mesh
          filename="package://robotfin/meshes/Lidar_Link.STL" />
      </geometry>
      <material
        name="">
        <color
          rgba="0 0 0 1" />
      </material>
    </visual>
    <collision>
      <origin
        xyz="0 0 0"
        rpy="0 0 0" />
      <geometry>
        <mesh
          filename="package://robotfin/meshes/Lidar_Link.STL" />
      </geometry>
    </collision>
  </link>
  <joint name="lidar_link"
    type="fixed">
    <origin
      xyz="-0.12887 0 0.2"
      rpy="0 0 0.90255" />
    <parent
      link="base_link" />
    <child
      link="Lidar_Link" />
    <axis
      xyz="0 0 0" />
  </joint>
  <link  name="Right_Wheel_Link">
    <inertial>
      <origin
        xyz="-0.0840728708421494 -2.81435039912699E-18 2.75148704505906E-18"
        rpy="0 0 0" />
      <mass
        value="2.23208588786701" />
      <inertia
        ixx="0.0150507702527097"
        ixy="1.41062359115593E-18"
        ixz="-3.99638870865354E-19"
        iyy="0.00801207149472829"
        iyz="3.25260651745651E-19"
        izz="0.00801207149472829" />
    </inertial>
    <visual>
      <origin
        xyz="0 0 0"
        rpy="0 0 0" />
      <geometry>
        <mesh
          filename="package://robotfin/meshes/Right_Wheel_Link.STL" />
      </geometry>
      <material
        name="">
        <color
          rgba="0.752941176470588 0.752941176470588 0.752941176470588 1" />
      </material>
    </visual>
    <collision>
      <origin
        xyz="0 0 0"
        rpy="0 0 0" />
      <geometry>
        <mesh
          filename="package://robotfin/meshes/Right_Wheel_Link.STL" />
      </geometry>
    </collision>
  </link>
  <joint name="right_link"
    type="continuous">
    <origin
      xyz="0.01 0 0"
      rpy="2.9765 0 3.1416" />
    <parent
      link="base_link" />
    <child
      link="Right_Wheel_Link" />
    <axis
      xyz="1 0 0" />
  </joint>
  <link  name="Left_Wheel_Link">
    <inertial>
      <origin
        xyz="-0.083442562384682 6.01930980637447E-17 -1.62014703188828E-17"
        rpy="0 0 0" />
      <mass
        value="2.23208588786701" />
      <inertia
        ixx="0.0150507702527097"
        ixy="-7.14758075911117E-19"
        ixz="8.27846035518381E-19"
        iyy="0.0080120714947283"
        iyz="-8.67361737988404E-19"
        izz="0.0080120714947283" />
    </inertial>
    <visual>
      <origin
        xyz="0 0 0"
        rpy="0 0 0" />
      <geometry>
        <mesh
          filename="package://robotfin/meshes/Left_Wheel_Link.STL" />
      </geometry>
      <material
        name="">
        <color
          rgba="0.752941176470588 0.752941176470588 0.752941176470588 1" />
      </material>
    </visual>
    <collision>
      <origin
        xyz="0 0 0"
        rpy="0 0 0" />
      <geometry>
        <mesh
          filename="package://robotfin/meshes/Left_Wheel_Link.STL" />
      </geometry>
    </collision>
  </link>
  <joint name="left_link"
    type="continuous">
    <origin
      xyz="-0.26837 0 0"
      rpy="-2.1829 0 0" />
    <parent
      link="base_link" />
    <child
      link="Left_Wheel_Link" />
    <axis
      xyz="1 0 0" />
  </joint>
  <transmission name="tran1">
    <type>transmission_interface/SimpleTransmission</type>
    <joint name="left_link">
      <hardwareInterface>EffortJointInterface</hardwareInterface>
    </joint>
    <actuator name="motor1">
      <hardwareInterface>EffortJointInterface</hardwareInterface>
      <mechanicalReduction>1</mechanicalReduction>
    </actuator>
  </transmission>
  <transmission name="tran2">
    <type>transmission_interface/SimpleTransmission</type>
    <joint name="right_link">
      <hardwareInterface>EffortJointInterface</hardwareInterface>
    </joint>
    <actuator name="motor2">
      <hardwareInterface>EffortJointInterface</hardwareInterface>
      <mechanicalReduction>1</mechanicalReduction>
    </actuator>
  </transmission>
</robot>